
WARNING:tensorflow:No training configuration found in save file: the model was *not* compiled. Compile it manually.
INFO:root:predictions: [7, 2, 1, 0, 4, 1, 4, 9, 5, 9, 0, 6, 9, 0, 1, 5, 9, 7, 5, 4, 9, 6, 6, 5, 4, 0, 7, 4, 0, 1, 3, 1]
INFO:root:labels: [7 2 1 0 4 1 4 9 5 9 0 6 9 0 1 5 9 7 3 4 9 6 6 5 4 0 7 4 0 1 3 1]
INFO:root:test loss: 0.05941576510667801, test accuracy: 0.96875
WARNING:tensorflow:Model was constructed with shape (None, 28, 28, 1) for input Tensor("conv2d_input:0", shape=(None, 28, 28, 1), dtype=float32), but it was called on an input with incompatible shape (32, 10).
ERROR:grpc._server:Exception calling application: input tensor must have rank 4
Traceback (most recent call last):
  File "/home/greenmon/.pyenv/versions/tensorflow-env/lib/python3.7/site-packages/tensorflow/python/framework/tensor_shape.py", line 930, in merge_with
    self.assert_same_rank(other)
  File "/home/greenmon/.pyenv/versions/tensorflow-env/lib/python3.7/site-packages/tensorflow/python/framework/tensor_shape.py", line 985, in assert_same_rank
    (self, other))
ValueError: Shapes (32, 10) and (None, None, None, None) must have the same rank

During handling of the above exception, another exception occurred:

Traceback (most recent call last):
  File "/home/greenmon/.pyenv/versions/tensorflow-env/lib/python3.7/site-packages/tensorflow/python/framework/tensor_shape.py", line 1015, in with_rank
    return self.merge_with(unknown_shape(rank=rank))
  File "/home/greenmon/.pyenv/versions/tensorflow-env/lib/python3.7/site-packages/tensorflow/python/framework/tensor_shape.py", line 936, in merge_with
    raise ValueError("Shapes %s and %s are not compatible" % (self, other))
ValueError: Shapes (32, 10) and (None, None, None, None) are not compatible

During handling of the above exception, another exception occurred:

Traceback (most recent call last):
  File "/home/greenmon/.pyenv/versions/tensorflow-env/lib/python3.7/site-packages/tensorflow/python/ops/nn_ops.py", line 1039, in __init__
    input_shape.with_rank(num_spatial_dims + 2)
  File "/home/greenmon/.pyenv/versions/tensorflow-env/lib/python3.7/site-packages/tensorflow/python/framework/tensor_shape.py", line 1017, in with_rank
    raise ValueError("Shape %s must have rank %d" % (self, rank))
ValueError: Shape (32, 10) must have rank 4

During handling of the above exception, another exception occurred:

Traceback (most recent call last):
  File "/home/greenmon/.pyenv/versions/tensorflow-env/lib/python3.7/site-packages/grpc/_server.py", line 435, in _call_behavior
    response_or_iterator = behavior(argument, context)
  File "inference.py", line 50, in process_tensor
    result = self.model.process_data(parsed)
  File "inference.py", line 101, in process_data
    result = self.model(input_data)
  File "/home/greenmon/.pyenv/versions/tensorflow-env/lib/python3.7/site-packages/tensorflow/python/keras/engine/base_layer.py", line 968, in __call__
    outputs = self.call(cast_inputs, *args, **kwargs)
  File "/home/greenmon/.pyenv/versions/tensorflow-env/lib/python3.7/site-packages/tensorflow/python/keras/engine/sequential.py", line 277, in call
    return super(Sequential, self).call(inputs, training=training, mask=mask)
  File "/home/greenmon/.pyenv/versions/tensorflow-env/lib/python3.7/site-packages/tensorflow/python/keras/engine/network.py", line 719, in call
    convert_kwargs_to_constants=base_layer_utils.call_context().saving)
  File "/home/greenmon/.pyenv/versions/tensorflow-env/lib/python3.7/site-packages/tensorflow/python/keras/engine/network.py", line 888, in _run_internal_graph
    output_tensors = layer(computed_tensors, **kwargs)
  File "/home/greenmon/.pyenv/versions/tensorflow-env/lib/python3.7/site-packages/tensorflow/python/keras/engine/base_layer.py", line 968, in __call__
    outputs = self.call(cast_inputs, *args, **kwargs)
  File "/home/greenmon/.pyenv/versions/tensorflow-env/lib/python3.7/site-packages/tensorflow/python/keras/layers/convolutional.py", line 201, in call
    data_format=self._conv_op_data_format)
  File "/home/greenmon/.pyenv/versions/tensorflow-env/lib/python3.7/site-packages/tensorflow/python/ops/nn_ops.py", line 1042, in __init__
    "input tensor must have rank %d" % (num_spatial_dims + 2))
ValueError: input tensor must have rank 4
